Workbook

Sheet 1. Inputs
A1: INPUTS CONFIGURABLES - SMOKE TEST chpapp
A3: SLIDERS DE SENSIBILIDAD (variables principales) | F3: COMENTARIOS DEL USUARIO
B4: Cobertura eléctrica de la cogeneración | C4: 0.75 | E4: % del consumo eléctrico que cubre la cogeneración. Default 75%. | F4: ok
B5: Rendimiento eléctrico de la cogeneración | C5: 0.4 | E5: Eficiencia eléctrica del motor. Energía eléctrica generada / Energía del combustible (PCI). Default 40%. | F5: ok
B6: Rendimiento térmico de la cogeneración | C6: 0.25 | E6: Eficiencia térmica recuperada de gases de escape. Default 25%. | F6: ok
B7: Eficiencia de la caldera reemplazada | C7: 0.85 | E7: Eficiencia térmica de la caldera actual del cliente. Default 85%. | F7: ok
A9: CONVERSIONES Y FACTORES TÉCNICOS
B10: Conversión kWh a GJ (3.6 MJ/kWh) | C10: 0.0036 | E10: Factor de conversión. 1 kWh = 3.6 MJ = 0.0036 GJ. | F10: ok
B11: Factor PCS a PCI (conversión gas) | C11: 1.11 | E11: Factura ENGIE viene en PCS. Para combustible térmico se usa PCI. PCS / 1.11 = PCI. | F11: ok
B12: Horas mensuales estándar para capacidad | C12: ='2. Factura CFE sep24'!C10*24 -> 720 | E12: Horas del mes = días facturados × 24. Para septiembre (30 días) = 720 h. Para 31 días = 744 h. Para febrero (28 o 29) = 672 o 696 h. | F12: Resuelto: ahora apunta a días × 24 de la factura CFE.
B13: Factor 0.57 (cobro CFE GDMTH demanda) | C13: 0.57 | E13: CFE GDMTH cobra capacidad/distribución sobre MIN(kw_max, demanda_promedio/0.57). Aplica techo al resultado. | F13: ok
A15: INVERSIÓN
B16: Costo unitario USD/kW | C16: 1400 | E16: Costo de instalación de cogeneración por kW de capacidad nominal. | F16: ok
B17: Tipo de cambio MXN/USD | C17: 17.5 | E17: Tipo de cambio para convertir inversión USD a MXN. | F17: ok
B18: Tasa ISR para beneficio fiscal año 1 | C18: 0.3 | E18: Art. 34 fracción XIII LISR. Cogeneración eficiente certificada CRE permite deducción inmediata 100%. Beneficio = inversión × 30%. | F18: ok
B19: Horizonte de proyección (años) | C19: 15 | E19: Años para el flujo proyectado y cálculo de payback. | F19: ok
A21: O&M (operación y mantenimiento)
B22: Costo O&M por kWh cubierto | C22: 0.3 | E22: Operación y mantenimiento de la cogeneración. 0.30 MXN por cada kWh generado. | F22: ok
A24: PARÁMETROS DEL CLIENTE PARA CELs (CRE)
B25: RefH (medio térmico) | C25: 0.82 | E25: Para gases_combustion: 0.82. Vapor o agua caliente: 0.90. (Documento CRE). | F25: ok
B26: fp (nivel tensión) | C26: 0.94 | E26: Para 1-34 kV: 0.94. Para 69-85 kV: 0.96. Para >115 kV: 0.97 (CRE). | F26: ok
B27: RefE (tramo capacidad y altitud) | C27: 0.44 | E27: Tabla CRE. Capacidad 0.5-6 MW, altitud >1500m: 0.44. (varía por tramo). | F27: ok
B28: Altitud msnm (informativa) | C28: 1721 | E28: Salamanca, Gto. >1500m define la tabla de RefE. | F28: ok

Sheet 2. Factura CFE sep24
A1: FACTURA CFE GDMTH - IBERICA TILES - SEPTIEMBRE 2024
A3: IDENTIFICACIÓN
B4: Cliente | C4: IBERICA TILES SAPI DE CV | E4: Razón social del receptor.
B5: RFC | C5: ITI170630377
B6: Número de servicio (RPU) | C6: 052231189271
B7: Tarifa | C7: GDMTH
B8: Multiplicador | C8: 2800 | E8: Multiplicador del medidor.
B9: Periodo facturado | C9: 31 AGO 24 - 30 SEP 24
B10: Días facturados | C10: 30
B11: Carga conectada (kW) | C11: 3200
B12: Demanda contratada (kW) | C12: 3200
A14: CONSUMO POR HORARIO (kWh)
B15: kWh Base | C15: 408800
B16: kWh Intermedia | C16: 630000
B17: kWh Punta | C17: 61600
B18: Total kWh | C18: =C15+C16+C17 -> 1100400 | E18: Suma de los tres horarios.
A20: DEMANDAS POR HORARIO (kW)
B21: kW Base | C21: 3444
B22: kW Intermedia | C22: 3444
B23: kW Punta | C23: 3416
B24: kW Max | C24: 3444 | E24: Máxima demanda en cualquier horario. Para GDMTH septiembre = 3,444 kW.
B25: Demanda promedio actual / 0.57 | C25: =CEILING(C18/('1. Inputs'!C12*'1. Inputs'!C13),1) -> 2682 | E25: Total kWh / (720 × 0.57) redondeado al entero superior. Aplica techo (CEILING). | F25: Confirmar que en esta fórmula, 720 aplica porque es el número de horas del mes (septiembre). Si fuera un mes de 31 días, tendría que ser 744. Si fuera Febrero, tendrían que ser las horas correspondientes a un mes de 28 o 29 días, según corresponda.
A27: FACTOR POTENCIA
B28: kVArh | C28: 352800
B29: Factor potencia % | C29: 0.9523
A31: COSTOS POR COMPONENTE MEM (MXN, pre-IVA)
B32: Suministro (cargo fijo) | C32: 362.6
B33: Distribución (cargo demanda) | C33: 272893.5 | E33: Cargo demanda CFE. Se cobra sobre MIN(kw_max, demanda_promedio/0.57).
B34: Transmisión | C34: 194660.76
B35: CENACE | C35: 7152.6
B36: Generación B | C36: 380306.64
B37: Generación I | C37: 1143765
B38: Generación P | C38: 129218.32
B39: Capacidad (cargo demanda) | C39: 1136336.6 | E39: Cargo demanda CFE. Se cobra sobre MIN(kw_max_punta, demanda_promedio/0.57).
B40: SCnMEM (servicios NO MEM) | C40: 6822.48
B41: Total componentes (suma sub-cargos) | C41: =SUM(C32:C40) -> 3271518.5 | F41: ok
B42: Bonificación Factor de Potencia | C42: -3271.52 | E42: Bonificación si FP > 90%, penalización si FP < 90%. Aquí bonificación (negativa = a favor cliente).
B43: Subtotal (pre-IVA) | C43: =C41+C42 -> 3268247 | F43: ok
B44: IVA 16% | C44: 522919.51
B45: Total con IVA | C45: =C43+C44 -> 3791166.5 | E45: Total facturado del periodo (sin DAP ni adeudos previos). | F45: ok
...

Sheet 3. Factura PPA sep24
A1: FACTURA PPA - IBERICA TILES - SEPTIEMBRE 2024 (GIN)
A3: IDENTIFICACIÓN
B4: Suministrador | C4: GENERACION INDUSTRIAL
B5: RFC suministrador | C5: GIN040707G89
B6: Cliente (receptor) | C6: IBERICA TILES
B7: RFC receptor | C7: ITI170630377
B8: Serie - Folio | C8: GI01 01312
B9: RPU (centro de carga) | C9: 52200951158
B10: Periodo facturado | C10: 01 al 30 de septiembre 2024
B11: Días facturados | C11: 30
B12: Fecha factura | C12: 09/10/2024
A14: CONSUMO Y PRECIO
B15: Consumo (kWh) | C15: 2060135 | E15: Cantidad facturada por el suministrador. NO viene desglosada por horario.
B16: Consumo (MWh) | C16: =C15/1000 -> 2060.135 | F16: ok
B17: Precio unitario MXN/kWh | C17: 2.0306 | E17: Precio combinado (energía + cargos CENACE). NO se desglosa en la factura. | F17: ok
A19: TOTALES
B20: Subtotal MXN (pre-IVA) | C20: 4183310.1 | F20: ok
B21: Verificación subtotal = kWh × precio | C21: =C15*C17 -> 4183310.1 | E21: Verificación: cantidad × precio unitario debe igualar subtotal (tolerancia redondeo).
B22: Diferencia (tolerancia esperada < $5) | C22: =ABS(C20-C21) -> 0.0010000006
B23: IVA 16% | C23: 669329.62
B24: Total con IVA | C24: 4852639.8
B25: Verificación total = subtotal × 1.16 | C25: =C20*1.16 -> 4852639.8
A27: DATOS DEL CONTRATO PPA (ficha del cliente)
B28: Precio fijo inicial USD/MWh | C28: 71.8 | E28: Del contrato base. Se actualiza por INPC en cada aniversario.
B29: Fecha inicio suministro | C29: 01/05/2024
B30: Energía contratada anual (MWh) | C30: 26987.82
B31: Capacidad máxima (kW) | C31: 4075
B32: División CENACE | C32: Bajío
B33: Bloque contratado sep-24 (MWh) | C33: 2333 | E33: Bloque contratado para septiembre 2024 según contrato. Para detectar excedentes.
B34: Banda de tolerancia (110%) | C34: =C33*1.1 -> 2566.3 | E34: Umbral hasta el cual el precio fijo aplica. Excedentes se cobran a precio mercado CENACE. | F34: ok
B35: ¿Excedente detectado? | C35: =IF(C16>C34,"SÍ EXCEDENTE","NO") -> NO | E35: Si consumo > 110% del bloque, hay excedente sobre precio mercado. | F35: ok

Sheet 4. Factura Gas sep24
A1: FACTURA GAS NATURAL - IBERICA TILES - SEPTIEMBRE 2024 (ENGIE)
A3: IDENTIFICACIÓN
B4: Suministrador | C4: GDF SUEZ MEXICO COMERCIALIZADORA (ENGIE)
B5: RFC suministrador | C5: TRA0002119W1
B6: Cliente | C6: IBERICA TILES SAPI DE CV
B7: RFC receptor | C7: ITI170630377
B8: Número de cliente | C8: 610002800
B9: Cuenta contrato | C9: 5100096634
B10: Folio | C10: I00000607
B11: Periodo facturado | C11: 01.09.2024 al 30.09.2024
B12: Días facturados | C12: 30
B13: Tipo servicio | C13: Comercialización Gas - Guadalajara
B14: Punto suministro | C14: 11067
A16: CONSUMO Y PODER CALORÍFICO
B17: Consumo m3 corregidos | C17: 3098657
B18: Poder calorífico (GJ/m³) | C18: 0.037740298 | E18: PCS (poder calorífico superior). Para combustible se usa PCI = PCS / 1.11.
B19: Total GJ (PCS) | C19: =C17*C18 -> 116944.24 | F19: ok
B20: Total GJ (PCI) - aplicable a cogeneración | C20: =C19/'1. Inputs'!C11 -> 105355.17 | E20: GJ PCI = GJ PCS / 1.11. Es el contenido energético neto del combustible. | F20: ok
A22: CARGOS Y PRECIOS (MXN, pre-IVA)
B23: Transporte por ducto | C23: 2867596.1 | E23: 78102101 - Transporte por ducto.
B24: Precio unitario transporte ($/GJ) | C24: 24.52
B25: Compraventa de gas | C25: 4393784.1 | E25: 83101601 - Compraventa de gas natural.
B26: Precio unitario gas ($/GJ) | C26: 37.57
B27: Subtotal (pre-IVA) | C27: =C23+C25 -> 7261380.3 | F27: ok
B28: Verificación subtotal | C28: 7261380.3 | F28: ok
B29: IVA 16% | C29: 1161820.8
B30: Total con IVA | C30: 8423201.1
A32: PRECIO PROMEDIO DEL GAS
B33: Precio promedio ($/GJ PCS) | C33: =C27/C19 -> 62.092673 | E33: Subtotal / GJ totales (en PCS). Costo total del gas por GJ entregado. | F33: ok
B34: Precio promedio ($/GJ PCI) | C34: =C27/C20 -> 68.922867 | E34: Subtotal / GJ PCI. Costo del combustible energético neto. Para cogeneración usar este. | F34: ok

Sheet 5. Parametros cliente
A1: PARÁMETROS DEL CLIENTE - IBERICA TILES
A3: IDENTIFICACIÓN
B4: Cliente | C4: IBERICA TILES SAPI DE CV | F4: ok
B5: Ubicación | C5: Salamanca, Guanajuato | F5: ok
A7: PARÁMETROS REGULATORIOS PARA CÁLCULO DE CELs
B8: Medio térmico recuperado | C8: gases_combustion | E8: Define RefH. Para gases_combustion: RefH = 0.82. | F8: ok
B9: Nivel de tensión | C9: 1-34 kV | E9: Define fp (factor pérdidas). Para 1-34 kV: fp = 0.94. | F9: ok
B10: Altitud (msnm) | C10: 1721 | E10: Para >1500m aplica una tabla de RefE distinta. | F10: ok
B11: Tipo motor | C11: combustion_interna | F11: ok
A13: FACTORES APLICABLES (tomados de hoja Inputs)
B14: RefH (factor calor) | C14: ='1. Inputs'!C25 -> 0.82 | F14: ok
B15: fp (factor pérdidas) | C15: ='1. Inputs'!C26 -> 0.94 | F15: ok
B16: RefE (factor electricidad) | C16: ='1. Inputs'!C27 -> 0.44 | F16: ok
B17: RefE' (RefE × fp) | C17: =C16*C15 -> 0.4136 | E17: RefE ajustado por pérdidas: RefE' = RefE × fp. | F17: ok

Sheet 6. Dashboard Contab CFE
A1: DASHBOARD CONTABILIDAD ENERGÉTICA - CFE GDMTH - SEPTIEMBRE 2024
A3: KPIs PRINCIPALES
B4: Meses analizados | C4: 1
B5: Consumo total (kWh) | C5: ='2. Factura CFE sep24'!C18 -> 1100400 | F5: ok
B6: Consumo total (MWh) | C6: =C5/1000 -> 1100.4 | F6: ok
B7: Costo total del periodo (pre-IVA) | C7: ='2. Factura CFE sep24'!C43 -> 3268247 | F7: ok
B8: Costo unitario promedio ($/kWh) | C8: =C7/C5 -> 2.9700536 | E8: Costo total pre-IVA / Total kWh. Es el $/kWh efectivo de CFE GDMTH. | F8: ok
A10: CONSUMO POR HORARIO
B11: kWh Base | C11: ='2. Factura CFE sep24'!C15 -> 408800 | F11: ok
B12: kWh Intermedia | C12: ='2. Factura CFE sep24'!C16 -> 630000 | F12: ok
B13: kWh Punta | C13: ='2. Factura CFE sep24'!C17 -> 61600 | F13: ok
B14: % Base | C14: =C11/C5 -> 0.37150127 | F14: ok
B15: % Intermedia | C15: =C12/C5 -> 0.57251908 | F15: ok
B16: % Punta | C16: =C13/C5 -> 0.055979644 | F16: ok
A18: DEMANDAS Y FACTOR POTENCIA
B19: kW Max | C19: ='2. Factura CFE sep24'!C24 -> 3444 | F19: ok
B20: kW Punta | C20: ='2. Factura CFE sep24'!C23 -> 3416 | F20: ok
B21: Factor de potencia | C21: ='2. Factura CFE sep24'!C29 -> 0.9523 | F21: ok
A23: COSTOS UNITARIOS POR HORARIO ($/kWh)
B24: $/kWh Base (Generación B) | C24: ='2. Factura CFE sep24'!C48 -> 0.9303 | F24: ok
B25: $/kWh Intermedia (Generación I) | C25: ='2. Factura CFE sep24'!C49 -> 1.8155 | F25: ok
B26: $/kWh Punta (Generación P) | C26: ='2. Factura CFE sep24'!C50 -> 2.0977 | F26: ok
B27: $/kWh promedio energía | C27: ='2. Factura CFE sep24'!C51 -> 1.5024445 | F27: ok
A29: COSTOS POR COMPONENTE
B30: Energía (B+I+P) | C30: ='2. Factura CFE sep24'!C36+'2. Factura CFE sep24'!C37+'2. Factura CFE sep24'!C38 -> 1653290 | F30: ok
B31: Capacidad | C31: ='2. Factura CFE sep24'!C39 -> 1136336.6 | F31: ok
B32: Distribución | C32: ='2. Factura CFE sep24'!C33 -> 272893.5 | F32: ok
B33: Transmisión | C33: ='2. Factura CFE sep24'!C34 -> 194660.76 | F33: ok
B34: CENACE + SCnMEM | C34: ='2. Factura CFE sep24'!C35+'2. Factura CFE sep24'!C40 -> 13975.08 | F34: ok
B35: Suministro (fijo) | C35: ='2. Factura CFE sep24'!C32 -> 362.6 | F35: ok
B36: Bonificación FP | C36: ='2. Factura CFE sep24'!C42 -> -3271.52 | F36: ok
B37: Subtotal | C37: =SUM(C30:C36) -> 3268247 | F37: op

Sheet 7. Dashboard Contab PPA
A1: DASHBOARD CONTABILIDAD ENERGÉTICA - PPA CALIFICADO (GIN) - SEPTIEMBRE 2024
A3: KPIs PRINCIPALES
B4: Meses analizados | C4: 1
B5: Consumo total (kWh) | C5: ='3. Factura PPA sep24'!C15 -> 2060135
B6: Consumo total (MWh) | C6: =C5/1000 -> 2060.135
B7: Costo total del periodo (pre-IVA) | C7: ='3. Factura PPA sep24'!C20 -> 4183310.1
B8: Precio promedio ($/kWh) | C8: =C7/C5 -> 2.0306 | E8: Subtotal / consumo. Es el $/kWh efectivo PPA (combinado energía + cargos CENACE).
A10: DETALLES DEL CONTRATO PPA
B11: Suministrador | C11: ='3. Factura PPA sep24'!C4 -> GENERACION INDUSTRIAL
B12: Precio fijo contractual (USD/MWh) | C12: ='3. Factura PPA sep24'!C28 -> 71.8
B13: Capacidad contratada (kW) | C13: ='3. Factura PPA sep24'!C31 -> 4075
B14: Energía contratada anual (MWh) | C14: ='3. Factura PPA sep24'!C30 -> 26987.82
A16: BLOQUE CONTRATADO vs CONSUMO REAL
B17: Bloque contratado sep-24 (MWh) | C17: ='3. Factura PPA sep24'!C33 -> 2333
B18: Consumo real sep-24 (MWh) | C18: =C6 -> 2060.135
B19: % consumo vs bloque | C19: =C18/C17 -> 0.88304115 | E19: Si >110%, hay excedente que se cobra a precio mercado CENACE.
B20: Banda tolerancia 110% (MWh) | C20: =C17*1.1 -> 2566.3
B21: Excedente (MWh) | C21: =MAX(0,C18-C20) -> 0
B22: Estado | C22: =IF(C21>0,"EXCEDENTE","Dentro de banda") -> Dentro de banda
A24: DIFERENCIA RESPECTO A FORMATO CFE GDMTH
B25: PPA NO tiene desglose por horario (Base/Intermedia/Punta).
B26: PPA NO tiene cargo separado de Capacidad ni Distribución sobre demanda kW.
B27: PPA cobra UN solo precio MXN/kWh combinado (energía + cargos CENACE no desglosados).
B28: Excedentes sobre el 110% del bloque se cobran a precio mercado CENACE de la zona.

Sheet 8. Dashboard Cogen CFE
A1: DASHBOARD COGENERACIÓN - CFE GDMTH - SEPTIEMBRE 2024
A3: INPUTS DEL ANÁLISIS
B4: Cobertura eléctrica | C4: ='1. Inputs'!C4 -> 0.75 | F4: ok
B5: Rendimiento eléctrico | C5: ='1. Inputs'!C5 -> 0.4 | F5: ok
B6: Rendimiento térmico | C6: ='1. Inputs'!C6 -> 0.25 | F6: ok
B7: Eficiencia caldera | C7: ='1. Inputs'!C7 -> 0.85 | F7: ok
A9: CONSUMO Y COBERTURA
B10: Total kWh del mes (factura) | C10: ='2. Factura CFE sep24'!C18 -> 1100400 | F10: ok
B11: kWh cubiertos por cogeneración | C11: =C10*C4 -> 825300 | E11: Total kWh × Cobertura. Es la energía que la cogeneración va a generar. | F11: ok
B12: kWh post-cogeneración (CFE) | C12: =C10-C11 -> 275100 | E12: Lo que el cliente seguiría comprando a CFE. | F12: ok
A14: ASIGNACIÓN GREEDY DE COBERTURA POR HORARIO
B15: Asignación greedy. Primero cubre PUNTA (más caro), luego INTERMEDIA, luego BASE. | F15: ok
B16: kWh cubierto en Punta | C16: =MIN('2. Factura CFE sep24'!C17,C11) -> 61600 | F16: ok
B17: Resto cobertura después de Punta | C17: =MAX(0,C11-C16) -> 763700 | F17: ok
B18: kWh cubierto en Intermedia | C18: =MIN('2. Factura CFE sep24'!C16,C17) -> 630000 | F18: ok
B19: Resto cobertura después de Intermedia | C19: =MAX(0,C17-C18) -> 133700 | F19: ok
B20: kWh cubierto en Base | C20: =MIN('2. Factura CFE sep24'!C15,C19) -> 133700
A22: AHORRO POR COMPONENTE - ENERGÍA
B23: Ahorro Energía Punta | C23: =C16*'2. Factura CFE sep24'!C50 -> 129218.32 | F23: ok
B24: Ahorro Energía Intermedia | C24: =C18*'2. Factura CFE sep24'!C49 -> 1143765 | F24: ok
B25: Ahorro Energía Base | C25: =C20*'2. Factura CFE sep24'!C48 -> 124381.11 | F25: ok
B26: TOTAL Ahorro Energía | C26: =SUM(C23:C25) -> 1397364.4 | F26: ok
A28: AHORRO POR COMPONENTE - CAPACIDAD
B29: kW facturado actual para Capacidad | C29: ='2. Factura CFE sep24'!C54 -> 2682 | F29: ok
B30: Precio Capacidad ($/kW) | C30: ='2. Factura CFE sep24'!C55 -> 423.69 | F30: ok
B31: Demanda promedio POST cogen / 0.57 (ceiling) | C31: =CEILING(C12/('1. Inputs'!C12*'1. Inputs'!C13),1) -> 671 | E31: kWh_post_cogen / (720 × 0.57) redondeado arriba. Aplica CEILING en metodología CFE. | F31: ok. Confirmar que aplica kWh_post_cogen / (horas del mes × 0.57) redondeando arriba
B32: kW efectivo POST Capacidad (MIN) | C32: =MIN('2. Factura CFE sep24'!C23,C31) -> 671 | E32: MIN(kw_max_punta, demanda_post/0.57 redondeada). Asunción conservadora kw_max no cambia. | F32: ok
B33: Reducción de kW (Capacidad) | C33: =MAX(0,C29-C32) -> 2011 | F33: ok
B34: Ahorro Capacidad | C34: =C33*C30 -> 852040.59 | F34: ok
A36: AHORRO POR COMPONENTE - DISTRIBUCIÓN
B37: kW facturado actual para Distribución | C37: ='2. Factura CFE sep24'!C56 -> 2682 | F37: ok
B38: Precio Distribución ($/kW) | C38: ='2. Factura CFE sep24'!C57 -> 101.75 | F38: ok
B39: kW efectivo POST Distribución (MIN) | C39: =MIN('2. Factura CFE sep24'!C24,C31) -> 671 | E39: MIN(kw_max, demanda_post/0.57 redondeada). | F39: ok
B40: Reducción de kW (Distribución) | C40: =MAX(0,C37-C39) -> 2011 | F40: ok
B41: Ahorro Distribución | C41: =C40*C38 -> 204619.25 | F41: ok
A43: AHORRO POR COMPONENTE - OTROS SERVICIOS | F43: Se incluye una cuarta componente de ahorro, resultado de reducir los conceptos de Transmisión, CENACE y SCnMEM al reducir el consumo total de energía
B44: kWh facturado actual para Otros Servicios | C44: ='2. Factura CFE sep24'!C18 -> 1100400
B45: kWh post-cogeneración (CFE) | C45: =C12 -> 275100
B46: Reducción consumo (kWh) | C46: =C44-C45 -> 825300
B47: Precio Otros Servicio ($/kWh) | C47: ='2. Factura CFE sep24'!C63 -> 0.1896
...

Sheet 9. Dashboard Cogen PPA
A1: DASHBOARD COGENERACIÓN - PPA CALIFICADO (GIN) - SEPTIEMBRE 2024
A2: Suministro: Calificado (PPA) - GENERACION INDUSTRIAL
A4: INPUTS DEL ANÁLISIS
B5: Cobertura eléctrica | C5: ='1. Inputs'!C4 -> 0.75
B6: Rendimiento eléctrico | C6: ='1. Inputs'!C5 -> 0.4
B7: Rendimiento térmico | C7: ='1. Inputs'!C6 -> 0.25
B8: Eficiencia caldera | C8: ='1. Inputs'!C7 -> 0.85
A10: CONSUMO Y COBERTURA (sin desglose horario en PPA)
B11: Total kWh del mes (factura PPA) | C11: ='3. Factura PPA sep24'!C15 -> 2060135
B12: kWh cubiertos por cogeneración | C12: =C11*C5 -> 1545101.2 | E12: Total kWh × Cobertura. Misma lógica que CFE pero sin asignación greedy por horario.
B13: kWh post-cogeneración | C13: =C11-C12 -> 515033.75
A15: PRECIO PROMEDIO PPA Y AHORRO ELÉCTRICO (sin desglose por componente)
B16: Subtotal pre-IVA de factura | C16: ='3. Factura PPA sep24'!C20 -> 4183310.1
B17: Precio promedio MXN/kWh | C17: =C16/C11 -> 2.0306 | E17: Subtotal / consumo. Precio combinado (energía + cargos CENACE).
B18: AHORRO ELÉCTRICO MES (PPA) | C18: =C12*C17 -> 3137482.6 | E18: kWh cubiertos × precio promedio. UN solo componente. NO hay Capacidad ni Distribución.
A20: DIFERENCIA RESPECTO A CFE GDMTH
B21: PPA: ahorro electricidad = kWh cubierto × precio promedio único.
B22: CFE: ahorro electricidad = Ahorro Energía (greedy horario) + Ahorro Capacidad + Ahorro Distribución +Ahoro Otros Servicios
B23: Resto de componentes (caldera, gas cogen, O&M, CELs, energía limpia, inversión, payback): IDÉNTICOS a CFE.
A25: GAS DE COGENERACIÓN Y CALOR RECUPERADO (idéntico a CFE)
B26: GJ de gas requerido por cogeneración | C26: =C12*'1. Inputs'!C10/C6 -> 13905.911
B27: GJ de calor útil recuperado | C27: =C26*C7 -> 3476.4778
B28: GJ ahorrado en caldera (PCI) | C28: =C27/C8 -> 4089.9739
A30: PRECIOS Y COSTOS DE GAS
B31: Precio gas $/GJ PCI | C31: ='4. Factura Gas sep24'!C34 -> 68.922867
B32: Costo Gas para Cogeneración | C32: =C26*C31 -> 958435.28
B33: Ahorro Caldera | C33: =C28*C31 -> 281892.73
A35: O&M
B36: Costo O&M | C36: =C12*'1. Inputs'!C22 -> 463530.38
A38: RESUMEN P&L MENSUAL
B39: (+) Ahorro Electricidad (PPA) | C39: =C18 -> 3137482.6
B40: (+) Ahorro Caldera | C40: =C33 -> 281892.73
B41: Total Ingresos | C41: =C39+C40 -> 3419375.3
B42: (-) Costo Gas Cogen | C42: =-C32 -> -958435.28
B43: (-) O&M | C43: =-C36 -> -463530.38
B44: Total Gastos | C44: =C42+C43 -> -1421965.7
B45: AHORRO NETO MES | C45: =C41+C44 -> 1997409.7
A47: PROYECCIÓN ANUAL (mes × 12 - simplificada)
B48: Ahorro Electricidad anual proyectado | C48: =C18*12 -> 37649791
B49: Ahorro Caldera anual proyectado | C49: =C33*12 -> 3382712.7
...

Sheet 10. Validacion
A1: VALIDACIÓN COMPARATIVA - SMOKE TEST
B3: Indicador | C3: CFE GDMTH | D3: PPA Calificado | E3: Observación
A5: CONTABILIDAD ENERGÉTICA
B6: Consumo total (kWh) | C6: ='6. Dashboard Contab CFE'!C5 -> 1100400 | D6: ='7. Dashboard Contab PPA'!C5 -> 2060135 | E6: CFE: 1.1M kWh (consumo registrado). PPA: 2.06M kWh (consumo distinto, escenario teórico).
B7: Costo total pre-IVA | C7: ='6. Dashboard Contab CFE'!C7 -> 3268247 | D7: ='7. Dashboard Contab PPA'!C7 -> 4183310.1
B8: Costo unitario promedio ($/kWh) | C8: ='6. Dashboard Contab CFE'!C8 -> 2.9700536 | D8: ='7. Dashboard Contab PPA'!C8 -> 2.0306 | E8: CFE incluye desglose. PPA es precio combinado.
A10: COGENERACIÓN - INGRESOS
B11: Ahorro Electricidad MES | C11: ='8. Dashboard Cogen CFE'!C51 -> 2610501.2 | D11: ='9. Dashboard Cogen PPA'!C18 -> 3137482.6 | E11: CFE: suma 3 componentes. PPA: kWh cubierto × precio promedio.
B12: Ahorro Energía (solo CFE) | C12: ='8. Dashboard Cogen CFE'!C26 -> 1397364.4 | D12: ="N/A" -> N/A | E12: PPA no tiene desglose por horario.
B13: Ahorro Capacidad (solo CFE) | C13: ='8. Dashboard Cogen CFE'!C34 -> 852040.59 | D13: ="N/A" -> N/A | E13: PPA no cobra capacidad sobre demanda kW.
B14: Ahorro Distribución (solo CFE) | C14: ='8. Dashboard Cogen CFE'!C41 -> 204619.25 | D14: ="N/A" -> N/A | E14: PPA no cobra distribución sobre demanda kW.
B15: Ahorro Otros Servicios (Transm+CENACE+SCnMEM) | C15: ='8. Dashboard Cogen CFE'!C48 -> 156476.88 | D15: ="N/A" -> N/A | E15: Cuarto componente CFE: Transmisión + CENACE + SCnMEM, proporcionales al consumo. PPA no aplica.
B16: Ahorro Caldera MES | C16: ='8. Dashboard Cogen CFE'!C61 -> 150570.11 | D16: ='9. Dashboard Cogen PPA'!C33 -> 281892.73 | E16: Misma fórmula en ambos. Difiere por kWh cubierto distintos.
B17: Total Ingresos MES | C17: ='8. Dashboard Cogen CFE'!C69 -> 2761071.3 | D17: ='9. Dashboard Cogen PPA'!C41 -> 3419375.3
A19: COGENERACIÓN - GASTOS
B20: Costo Gas Cogen MES | C20: ='8. Dashboard Cogen CFE'!C60 -> 511938.38 | D20: ='9. Dashboard Cogen PPA'!C32 -> 958435.28
B21: O&M MES | C21: ='8. Dashboard Cogen CFE'!C64 -> 247590 | D21: ='9. Dashboard Cogen PPA'!C36 -> 463530.38
B22: Total Gastos MES | C22: =-'8. Dashboard Cogen CFE'!C72 -> 759528.38 | D22: =-'9. Dashboard Cogen PPA'!C44 -> 1421965.7
A24: AHORRO NETO
B25: AHORRO NETO MES | C25: ='8. Dashboard Cogen CFE'!C73 -> 2001542.9 | D25: ='9. Dashboard Cogen PPA'!C45 -> 1997409.7
B26: AHORRO NETO ANUAL PROYECTADO | C26: ='8. Dashboard Cogen CFE'!C80 -> 24018515 | D26: ='9. Dashboard Cogen PPA'!C52 -> 23968916 | E26: Mes × 12. Proyección lineal simple.
A28: CAPACIDAD Y CELs (deben ser idénticos cuando consumos sean iguales)
B29: Capacidad nominal kW | C29: ='8. Dashboard Cogen CFE'!C84 -> 1529 | D29: ='9. Dashboard Cogen PPA'!C56 -> 2862 | E29: Misma fórmula (ceiling max kWh/horas del mes). Difiere por consumos distintos.
B30: CELs anuales (MWh) | C30: ='8. Dashboard Cogen CFE'!C93 -> 2963.1139 | D30: ='9. Dashboard Cogen PPA'!C65 -> 5547.4507 | E30: Misma fórmula CRE Caso I. Difiere por kWh cubierto distintos.
B31: % Energía Limpia | C31: ='8. Dashboard Cogen CFE'!C94 -> 0.22439673 | D31: ='9. Dashboard Cogen PPA'!C66 -> 0.22439673
A33: INVERSIÓN Y PAYBACK
B34: Inversión MXN | C34: ='8. Dashboard Cogen CFE'!C98 -> 37460500 | D34: ='9. Dashboard Cogen PPA'!C71 -> 70119000
B35: Beneficio fiscal año 1 | C35: ='8. Dashboard Cogen CFE'!C99 -> 11238150 | D35: ='9. Dashboard Cogen PPA'!C72 -> 21035700
B36: Flujo año 1 con beneficio | C36: ='8. Dashboard Cogen CFE'!C100 -> 35256665 | D36: ='9. Dashboard Cogen PPA'!C73 -> 45004616
B37: Payback (años) | C37: ='8. Dashboard Cogen CFE'!C107 -> 1.0917557 | D37: ='9. Dashboard Cogen PPA'!C80 -> 2.0477897
A39: VERIFICACIONES INTERNAS DEL MODELO
B40: CFE: kWh asignados greedy = kWh cubierto? | C40: =IF(ABS(('8. Dashboard Cogen CFE'!C16+'8. Dashboard Cogen CFE'!C18+'8. Dashboard Cogen CFE'!C20)-'8. Dashboard Cogen CFE'!C11)<1,"OK","REVISAR") -> OK | D40: ="N/A" -> N/A | E40: Suma de los 3 horarios debe igualar la cobertura total.
B41: CFE: precio promedio horario × kWh = energía total? | C41: =IF(ABS('2. Factura CFE sep24'!C51*'2. Factura CFE sep24'!C18-('2. Factura CFE sep24'!C36+'2. Factura CFE sep24'!C37+'2. Factura CFE sep24'!C38))<5,"OK","REVISAR") -> OK | D41: ="N/A" -> N/A
B42: PPA: subtotal = kWh × precio? | C42: ="N/A" -> N/A | D42: =IF(ABS('3. Factura PPA sep24'!C20-'3. Factura PPA sep24'!C21)<5,"OK","REVISAR") -> OK
B43: Gas: subtotal calculado = subtotal factura? | C43: =IF(ABS('4. Factura Gas sep24'!C27-'4. Factura Gas sep24'!C28)<5,"OK","REVISAR") -> OK | D43: ='10. Validacion'!C42 -> N/A | E43: Misma factura de gas en ambos escenarios.
A45: NOTAS METODOLÓGICAS
B46: Las facturas CFE y PPA usadas son de septiembre 2024 (mismo mes) pero con CONSUMOS distintos.
B47: Esto es escenario teórico para validar fórmulas. NO comparar valores absolutos.
B48: Lo importante es validar que cada metodología (CFE vs PPA) aplica las fórmulas correctas a sus datos.
B49: Inversión, beneficio fiscal y payback: idéntica fórmula. Difieren por capacidades distintas (consumos distintos).
...

Sheet 11. KPI's control CFE
A3: # | B3: Indicador | C3: CFE GDMTH
A4: 1 | B4: ='10. Validacion'!B6 -> Consumo total (kWh) | C4: ='10. Validacion'!C6 -> 1100400
A5: 2 | B5: ='10. Validacion'!B7 -> Costo total pre-IVA | C5: ='10. Validacion'!C7 -> 3268247
A6: 3 | B6: ='10. Validacion'!B8 -> Costo unitario promedio ($/kWh) | C6: ='10. Validacion'!C8 -> 2.9700536
A7: 4 | B7: ='10. Validacion'!B11 -> Ahorro Electricidad MES | C7: ='10. Validacion'!C11 -> 2610501.2
A8: 5 | B8: Ahorro Caldera | C8: ='10. Validacion'!C16 -> 150570.11
A9: 6 | B9: Ingreso total | C9: ='10. Validacion'!C17 -> 2761071.3
A10: 7 | B10: ='10. Validacion'!B20 -> Costo Gas Cogen MES | C10: ='10. Validacion'!C20 -> 511938.38
A11: 8 | B11: ='10. Validacion'!B21 -> O&M MES | C11: ='10. Validacion'!C21 -> 247590
A12: 9 | B12: Gasto total | C12: ='10. Validacion'!C22 -> 759528.38
A13: 10 | B13: Ahorro NETO | C13: ='10. Validacion'!C25 -> 2001542.9
A14: 11 | B14: ='10. Validacion'!B29 -> Capacidad nominal kW | C14: ='10. Validacion'!C29 -> 1529
A15: 12 | B15: ='10. Validacion'!B34 -> Inversión MXN | C15: ='10. Validacion'!C34 -> 37460500
A16: 13 | B16: ='10. Validacion'!B30 -> CELs anuales (MWh) | C16: ='10. Validacion'!C30 -> 2963.1139
A17: 14 | B17: ='10. Validacion'!B31 -> % Energía Limpia | C17: ='10. Validacion'!C31 -> 0.22439673
A18: 15 | B18: ='10. Validacion'!B37 -> Payback (años) | C18: ='10. Validacion'!C37 -> 1.0917557

Sheet 12. KPI's control PPA
A3: # | B3: Indicador | C3: PPA Calificado
A4: 1 | B4: ='10. Validacion'!B6 -> Consumo total (kWh) | C4: ='10. Validacion'!D6 -> 2060135
A5: 2 | B5: ='10. Validacion'!B7 -> Costo total pre-IVA | C5: ='10. Validacion'!D7 -> 4183310.1
A6: 3 | B6: ='10. Validacion'!B8 -> Costo unitario promedio ($/kWh) | C6: ='10. Validacion'!D8 -> 2.0306
A7: 4 | B7: ='10. Validacion'!B11 -> Ahorro Electricidad MES | C7: ='10. Validacion'!D11 -> 3137482.6
A8: 5 | B8: Ahorro Caldera | C8: ='10. Validacion'!D16 -> 281892.73
A9: 6 | B9: Ingreso total | C9: ='10. Validacion'!D17 -> 3419375.3
A10: 7 | B10: ='10. Validacion'!B20 -> Costo Gas Cogen MES | C10: ='10. Validacion'!D20 -> 958435.28
A11: 8 | B11: ='10. Validacion'!B21 -> O&M MES | C11: ='10. Validacion'!D21 -> 463530.38
A12: 9 | B12: Gasto total | C12: ='10. Validacion'!D22 -> 1421965.7
A13: 10 | B13: Ahorro NETO | C13: ='10. Validacion'!D25 -> 1997409.7
A14: 11 | B14: ='10. Validacion'!B29 -> Capacidad nominal kW | C14: ='10. Validacion'!D29 -> 2862
A15: 12 | B15: ='10. Validacion'!B34 -> Inversión MXN | C15: ='10. Validacion'!D34 -> 70119000
A16: 13 | B16: ='10. Validacion'!B30 -> CELs anuales (MWh) | C16: ='10. Validacion'!D30 -> 5547.4507
A17: 14 | B17: ='10. Validacion'!B31 -> % Energía Limpia | C17: ='10. Validacion'!D31 -> 0.22439673
A18: 15 | B18: ='10. Validacion'!B37 -> Payback (años) | C18: ='10. Validacion'!D37 -> 2.0477897
